package ExceptionHandling;

public class ExceptionHandling5 {

	public static void main(String[] args) {
		// TODO Auto-generated method stub
		try {
			int a[] = new int[5];
			a[5] = 30 / 0;//
		} catch (ArrayIndexOutOfBoundsException e) {
			System.out.println("ArrayIndexOutOfBounds Exception occurs "+e);
		} catch (ArithmeticException e) {
			System.out.println("Arithmetic Exception occurs "+e);
		} catch (Exception e) {
			System.out.println("Parent Exception occurs "+e);
		}
		try {
			int a[] = new int[5];
			a[5] = 30 / 2;//
		} catch (ArithmeticException e) {
			System.out.println("Arithmetic Exception occurs "+e);
		} catch (ArrayIndexOutOfBoundsException e) {
			System.out.println("ArrayIndexOutOfBounds Exception occurs "+e);
		} catch (Exception e) {
			System.out.println("Parent Exception occurs "+e);
		}
		System.out.println("rest of the code");
	}
}
/**
* try block can have multiple catch block, but only one catch block will be executed 
* try can handle only one abnormal condition at a time
*/